import { render } from '@testing-library/react';
import { vi, beforeEach, afterEach } from 'vitest';
import { ErrorBoundary } from './ErrorBoundary';

const ThrowError = ({ shouldThrow }: { shouldThrow: boolean }) => {
  if (shouldThrow) {
    throw new Error('Test error message');
  }
  return <div>No error</div>;
};

describe('ErrorBoundary', () => {
  let consoleErrorSpy: ReturnType<typeof vi.spyOn>;

  beforeEach(() => {
    // Suppress console.error for error boundary tests to avoid noise in test output
    consoleErrorSpy = vi.spyOn(console, 'error').mockImplementation(() => {});
  });

  afterEach(() => {
    consoleErrorSpy.mockRestore();
  });

  it('should render children when there is no error', () => {
    const { getByText } = render(
      <ErrorBoundary>
        <ThrowError shouldThrow={false} />
      </ErrorBoundary>
    );

    expect(getByText('No error')).toBeTruthy();
  });

  it('should render error UI when there is an error', () => {
    const { getByText } = render(
      <ErrorBoundary>
        <ThrowError shouldThrow={true} />
      </ErrorBoundary>
    );

    expect(getByText('Test error message')).toBeTruthy();
    expect(getByText('Try again')).toBeTruthy();

    // Verify that React's error boundary mechanism was triggered
    expect(consoleErrorSpy).toHaveBeenCalled();
  });
});
